Workbook
Name Slicer_Product: #N/A

Sheet Basic Example
A1: Order Priority | B1: Ship Mode | C1: Customer Segment | D1: Product Category | E1: Product Sub-Category | F1: Region | G1: State or Province | H1: Order Date | I1: Ship Date | J1: Profit | K1: Units | L1: Sales | M1: Order ID
A2: High | B2: Express Air | C2: Corporate | D2: Office Supplies | E2: Pens & Art Supplies | F2: West | G2: Washington | H2: 42011 | I2: 42012 | J2: 4.56 | K2: 5 | L2: 13.01 | M2: 88522
A3: Not Specified | B3: Delivery Truck | C3: Home Office | D3: Furniture | E3: Chairs & Chairmats | F3: West | G3: California | H3: 42168 | I3: 42170 | J3: 4390.3665 | K3: 13 | L3: 6362.85 | M3: 90193
A4: Critical | B4: Regular Air | C4: Home Office | D4: Furniture | E4: Office Furnishings | F4: East | G4: New Jersey | H4: 42050 | I4: 42052 | J4: -53.8096 | K4: 22 | L4: 211.15 | M4: 90192
A5: Medium | B5: Regular Air | C5: Small Business | D5: Furniture | E5: Office Furnishings | F5: Central | G5: Minnesota | H5: 42136 | I5: 42138 | J5: 803.4705 | K5: 15 | L5: 1164.45 | M5: 86838
A6: Medium | B6: Regular Air | C6: Small Business | D6: Office Supplies | E6: Pens & Art Supplies | F6: Central | G6: Minnesota | H6: 42136 | I6: 42137 | J6: -24.03 | K6: 7 | L6: 22.23 | M6: 86838
A7: Medium | B7: Regular Air | C7: Small Business | D7: Office Supplies | E7: Pens & Art Supplies | F7: Central | G7: Minnesota | H7: 42136 | I7: 42137 | J7: -37.03 | K7: 4 | L7: 13.99 | M7: 86838
A8: Medium | B8: Regular Air | C8: Small Business | D8: Office Supplies | E8: Rubber Bands | F8: Central | G8: Minnesota | H8: 42136 | I8: 42137 | J8: -0.71 | K8: 4 | L8: 14.26 | M8: 86838
A9: Critical | B9: Regular Air | C9: Small Business | D9: Office Supplies | E9: Envelopes | F9: East | G9: New York | H9: 42102 | I9: 42103 | J9: -59.82 | K9: 8 | L9: 33.47 | M9: 86837
A10: Medium | B10: Regular Air | C10: Small Business | D10: Office Supplies | E10: Envelopes | F10: East | G10: New York | H10: 42152 | I10: 42152 | J10: 261.8757 | K10: 11 | L10: 379.53 | M10: 86839
A11: High | B11: Regular Air | C11: Small Business | D11: Office Supplies | E11: Rubber Bands | F11: East | G11: New York | H11: 42047 | I11: 42050 | J11: 2.63 | K11: 6 | L11: 18.8 | M11: 86836
A12: High | B12: Regular Air | C12: Small Business | D12: Technology | E12: Telephones and Communication | F12: East | G12: New York | H12: 42047 | I12: 42049 | J12: 652.7331 | K12: 8 | L12: 945.99 | M12: 86836
A13: High | B13: Regular Air | C13: Small Business | D13: Furniture | E13: Office Furnishings | F13: West | G13: Montana | H13: 42139 | I13: 42140 | J13: 314.4813 | K13: 17 | L13: 455.77 | M13: 90031
... A1953: High | B1953: Express Air | C1953: Consumer | D1953: Furniture | E1953: Office Furnishings | F1953: West | G1953: Wyoming | H1953: 42043 | I1953: 42046 | J1953: 349.485 | K1953: 5 | L1953: 506.5 | M1953: 87530

Sheet Intro
A1: OrderDate | B1: Region | C1: Sales
A2: 44197 | B2: East | C2: 6560
A3: 44217 | B3: East | C3: 5964
A4: 44203 | B4: West | C4: 3312
A5: 44217 | B5: East | C5: 1034
A6: 44206 | B6: South | C6: 4602
A7: 44210 | B7: East | C7: 4860
A8: 44205 | B8: East | C8: 7587
A9: 44206 | B9: West | C9: 7565
A10: 44214 | B10: South | C10: 2642
A11: 44204 | B11: East | C11: 7741
A12: 44226 | B12: East | C12: 5869

Sheet Intro Pivot
A3: Sum of Sales | B3: Column Labels
A4: Row Labels | B4: East | C4: South | D4: West | E4: Grand Total
A5: 44197 | B5: 6560 | C5: 0 | D5: 0 | E5: 6560
A6: 44203 | B6: 0 | C6: 0 | D6: 3312 | E6: 3312
A7: 44204 | B7: 7741 | C7: 0 | D7: 0 | E7: 7741
A8: 44205 | B8: 7587 | C8: 0 | D8: 0 | E8: 7587
A9: 44206 | B9: 0 | C9: 4602 | D9: 7565 | E9: 12167
A10: 44210 | B10: 4860 | C10: 0 | D10: 0 | E10: 4860
A11: 44214 | B11: 0 | C11: 2642 | D11: 0 | E11: 2642
A12: 44217 | B12: 6998 | C12: 0 | D12: 0 | E12: 6998
A13: 44226 | B13: 5869 | C13: 0 | D13: 0 | E13: 5869
A14: Grand Total | B14: 39615 | C14: 7244 | D14: 10877 | E14: 57736

Sheet Basic Pivot 1
A3: Row Labels | B3: Sum of Sales | C3: Sum of Profit | F3: Row Labels | G3: Sum of Sales
A4: Consumer | B4: 401778.37 | C4: 49894.99 | F4: California | G4: 288310.61
A5: Corporate | B5: 657784.53 | C5: 54444.191 | F5: New York | G5: 223930.48
A6: Home Office | B6: 464481.04 | C6: 54433.521 | F6: Illinois | G6: 98971.25
A7: Small Business | B7: 400293.94 | C7: 65304.91 | F7: Texas | G7: 93082.73
A8: Grand Total | B8: 1924337.9 | C8: 224077.61 | F8: Florida | G8: 87651.11
F9: Washington | G9: 83468.06
F10: Michigan | G10: 69641.81
F11: Ohio | G11: 69452.82
F12: District of Columbia | G12: 68946.66
F13: Massachusetts | G13: 59114.82
F14: Pennsylvania | G14: 52435.24
F15: Alabama | G15: 46826.45
F16: Colorado | G16: 45843.45
F17: Virginia | G17: 45282.87
F18: North Carolina | G18: 43983.3
F19: Minnesota | G19: 41671.26
F20: Indiana | G20: 41089.05
... F53: Grand Total | G53: 1924337.9

Sheet Basic Pivot 2
A2: Row Labels | B2: Sum of Sales
A3: California | B3: 288310.61
A4: New York | B4: 223930.48
A5: Illinois | B5: 98971.25
A6: Texas | B6: 93082.73
A7: Florida | B7: 87651.11
A8: Grand Total | B8: 791946.18

Sheet Ex 1 Pivot
A2: Row Labels | B2: Sum of Sales | C2: Sum of Profit | D2: Sum of Profit%
A3: California | B3: 288310.61 | C3: 37421.96 | D3: 0.12979737
A4: New York | B4: 223930.48 | C4: 27611.943 | D4: 0.12330587
A5: Illinois | B5: 98971.25 | C5: 12321.579 | D5: 0.12449655
A6: Texas | B6: 93082.73 | C6: 28078.851 | D6: 0.30165478
A7: Florida | B7: 87651.11 | C7: 86.70384 | D7: 0.00098919272
A8: Washington | B8: 83468.06 | C8: 3855.6117 | D8: 0.04619266
A9: Michigan | B9: 69641.81 | C9: 12307.552 | D9: 0.17672648
A10: Ohio | B10: 69452.82 | C10: 23410.842 | D10: 0.33707547
A11: District of Columbia | B11: 68946.66 | C11: 11677.363 | D11: 0.16936808
A12: Massachusetts | B12: 59114.82 | C12: 5293.784 | D12: 0.089550877
A13: Pennsylvania | B13: 52435.24 | C13: -1095.5065 | D13: -0.020892562
A14: Alabama | B14: 46826.45 | C14: -2418.0566 | D14: -0.051638691
... A52: Grand Total | B52: 1924337.9 | C52: 224077.61 | D52: 0.11644401

Sheet Ex 2
A1: OrderDate | B1: Region | C1: City | D1: Category | E1: Product | F1: Quantity | G1: UnitPrice | H1: TotalPrice
A2: 43831 | B2: East | C2: Boston | D2: Bars | E2: Carrot | F2: 33 | G2: 1.77 | H2: ='Ex 2'!$F2*'Ex 2'!$G2 -> 58.41
A3: 43834 | B3: East | C3: Boston | D3: Crackers | E3: Whole Wheat | F3: 87 | G3: 3.49 | H3: ='Ex 2'!$F3*'Ex 2'!$G3 -> 303.63
A4: 43837 | B4: West | C4: Los Angeles | D4: Cookies | E4: Chocolate Chip | F4: 58 | G4: 1.87 | H4: ='Ex 2'!$F4*'Ex 2'!$G4 -> 108.46
A5: 43840 | B5: East | C5: New York | D5: Cookies | E5: Chocolate Chip | F5: 82 | G5: 1.87 | H5: ='Ex 2'!$F5*'Ex 2'!$G5 -> 153.34
A6: 43843 | B6: East | C6: Boston | D6: Cookies | E6: Arrowroot | F6: 38 | G6: 2.18 | H6: ='Ex 2'!$F6*'Ex 2'!$G6 -> 82.84
A7: 43846 | B7: East | C7: Boston | D7: Bars | E7: Carrot | F7: 54 | G7: 1.77 | H7: ='Ex 2'!$F7*'Ex 2'!$G7 -> 95.58
A8: 43849 | B8: East | C8: Boston | D8: Crackers | E8: Whole Wheat | F8: 149 | G8: 3.49 | H8: ='Ex 2'!$F8*'Ex 2'!$G8 -> 520.01
A9: 43852 | B9: West | C9: Los Angeles | D9: Bars | E9: Carrot | F9: 51 | G9: 1.77 | H9: ='Ex 2'!$F9*'Ex 2'!$G9 -> 90.27
A10: 43855 | B10: East | C10: New York | D10: Bars | E10: Carrot | F10: 100 | G10: 1.77 | H10: ='Ex 2'!$F10*'Ex 2'!$G10 -> 177
A11: 43858 | B11: East | C11: New York | D11: Snacks | E11: Potato Chips | F11: 28 | G11: 1.35 | H11: ='Ex 2'!$F11*'Ex 2'!$G11 -> 37.8
A12: 43861 | B12: East | C12: Boston | D12: Cookies | E12: Arrowroot | F12: 36 | G12: 2.18 | H12: ='Ex 2'!$F12*'Ex 2'!$G12 -> 78.48
A13: 43864 | B13: East | C13: Boston | D13: Cookies | E13: Chocolate Chip | F13: 31 | G13: 1.87 | H13: ='Ex 2'!$F13*'Ex 2'!$G13 -> 57.97
... A247: 44562 | B247: West | C247: Los Angeles | D247: Cookies | E247: Oatmeal Raisin | F247: 56 | G247: 2.84 | H247: ='Ex 2'!$F247*'Ex 2'!$G247 -> 159.04

Sheet Ex 1 Pivot 2
A3: Years | B3: OrderDate | C3: Sum of TotalPrice
A4: 2020 | C4: 1256.97
B5: Jan | C5: 37.8
B6: Feb | C6: 36.45
B7: Mar | C7: 114.24
B8: Apr | C8: 493.92
B9: May | C9: 82.32
B10: Jun | C10: 47.04
B11: Jul | C11: 52.08
B12: Oct | C12: 191.52
B13: Nov | C13: 152.88
B14: Dec | C14: 48.72
A15: 2021 | C15: 394.8
B16: Feb | C16: 75.6
B17: Mar | C17: 203.28
B18: Apr | C18: 40.32
B19: Sep | C19: 33.6
B20: Oct | C20: 42
A21: Grand Total | C21: 1651.77

Sheet East
A1: OrderDate | B1: Region | C1: Sales
A2: 43831 | B2: East | C2: 15040
A3: 43834 | B3: East | C3: 47643
A4: 43837 | B4: East | C4: 25890
A5: 43840 | B5: East | C5: 49368
A6: 43843 | B6: East | C6: 35698
A7: 43846 | B7: East | C7: 34021
A8: 43849 | B8: East | C8: 28883
A9: 43852 | B9: East | C9: 12731
A10: 43855 | B10: East | C10: 20867

Sheet West
A1: OrderDate | B1: Region | C1: Sales
A2: 43831 | B2: West | C2: 14343
A3: 43834 | B3: West | C3: 17818
A4: 43837 | B4: West | C4: 15703
A5: 43840 | B5: West | C5: 43508
A6: 43843 | B6: West | C6: 36183
A7: 43846 | B7: West | C7: 27879
A8: 43849 | B8: West | C8: 28495
A9: 43852 | B9: West | C9: 43358
A10: 43855 | B10: West | C10: 48877

Sheet North
A1: OrderDate | B1: Region | C1: Sales
A2: 43831 | B2: North | C2: 27847
A3: 43834 | B3: North | C3: 26320
A4: 43837 | B4: North | C4: 35701
A5: 43840 | B5: North | C5: 48444
A6: 43843 | B6: North | C6: 42856
A7: 43846 | B7: North | C7: 41937
A8: 43849 | B8: North | C8: 32729
A9: 43852 | B9: North | C9: 26380
A10: 43855 | B10: North | C10: 34294

Sheet South
A1: OrderDate | B1: Region | C1: Sales
A2: 43831 | B2: South | C2: 19519
A3: 43834 | B3: South | C3: 10164
A4: 43837 | B4: South | C4: 24428
A5: 43840 | B5: South | C5: 15184
A6: 43843 | B6: South | C6: 29543
A7: 43846 | B7: South | C7: 20734
A8: 43849 | B8: South | C8: 17461
A9: 43852 | B9: South | C9: 34436
A10: 43855 | B10: South | C10: 17089

Sheet FAQ
A1: Page1 | B1: (All)
B3: Column Labels
A4: Row Labels | B4: Region | C4: Sales | D4: Grand Total
A5: 43831
A6: 14343
A7: 15040
A8: 19519
A9: 27847
A10: East
A11: North
A12: South
A13: West
A14: 43834
A15: 10164
A16: 17818
A17: 26320
A18: 47643
A19: East
A20: North
A21: South
A22: West
A23: 43837
A24: 15703
A25: 24428
A26: 25890
A27: 35701
A28: East
A29: North
A30: South
A31: West
A32: 43840
A33: 15184
A34: 43508
A35: 48444
A36: 49368
A37: East
A38: North
A39: South
A40: West
A41: 43843
...
